Workbook

Sheet 模板表单
A1: 项目名称 | C1: XX项目/XX项目补料计划/XX项目第XX批次 （如DZ1296项目电气预焊件、DZ1296框架补料计划、DZ1296框架第一批次） | I1: 编制： | J1: 张三 | K1: 下发时间 | L1: 46016 | M1: 版本号: (版本变更按V0、V1依次升序) | N1: V0/V1/V2…… | V1: 开工日期 | W1: 完工日期
A2: 序号 | B2: 代号 | C2: 名称 | D2: 所属代号 | E2: 所属部件 | F2: 所属数量 | G2: 单台数量 | H2: 计划数量 | I2: 材质 | J2: 单件重量 | K2: 单台总重 | L2: 属性 | M2: 工艺内容 | N2: 备注 | O2: 是否为发货件 | P2: 面漆颜色 | Q2: 标准编码 | R2: 标准品名 | S2: 工序类别 | T2: 制作工位 | U2: 制作小组/人员
K3: =G3*J3 -> 0 | Q3: =IF(AND(ISNUMBER(B3),L3="标准件"),_xlfn.XLOOKUP(B3,[1]编码对照表!$A:$A,[1]编码对照表!$E:$E),"-") -> - | R3: =IF(AND(ISNUMBER(B3),L3="标准件"),_xlfn.XLOOKUP(B3,[1]编码对照表!$A:$A,[1]编码对照表!$F:$F),"-") -> -
K4: =G4*J4 -> 0 | Q4: =IF(AND(ISNUMBER(B4),L4="标准件"),_xlfn.XLOOKUP(B4,[1]编码对照表!$A:$A,[1]编码对照表!$E:$E),"-") -> - | R4: =IF(AND(ISNUMBER(B4),L4="标准件"),_xlfn.XLOOKUP(B4,[1]编码对照表!$A:$A,[1]编码对照表!$F:$F),"-") -> -
K5: =G5*J5 -> 0 | Q5: =IF(AND(ISNUMBER(B5),L5="标准件"),_xlfn.XLOOKUP(B5,[1]编码对照表!$A:$A,[1]编码对照表!$E:$E),"-") -> - | R5: =IF(AND(ISNUMBER(B5),L5="标准件"),_xlfn.XLOOKUP(B5,[1]编码对照表!$A:$A,[1]编码对照表!$F:$F),"-") -> -
K6: =G6*J6 -> 0 | Q6: =IF(AND(ISNUMBER(B6),L6="标准件"),_xlfn.XLOOKUP(B6,[1]编码对照表!$A:$A,[1]编码对照表!$E:$E),"-") -> - | R6: =IF(AND(ISNUMBER(B6),L6="标准件"),_xlfn.XLOOKUP(B6,[1]编码对照表!$A:$A,[1]编码对照表!$F:$F),"-") -> -
K7: =G7*J7 -> 0 | Q7: =IF(AND(ISNUMBER(B7),L7="标准件"),_xlfn.XLOOKUP(B7,[1]编码对照表!$A:$A,[1]编码对照表!$E:$E),"-") -> - | R7: =IF(AND(ISNUMBER(B7),L7="标准件"),_xlfn.XLOOKUP(B7,[1]编码对照表!$A:$A,[1]编码对照表!$F:$F),"-") -> -
K8: =G8*J8 -> 0 | Q8: =IF(AND(ISNUMBER(B8),L8="标准件"),_xlfn.XLOOKUP(B8,[1]编码对照表!$A:$A,[1]编码对照表!$E:$E),"-") -> - | R8: =IF(AND(ISNUMBER(B8),L8="标准件"),_xlfn.XLOOKUP(B8,[1]编码对照表!$A:$A,[1]编码对照表!$F:$F),"-") -> -
K9: =G9*J9 -> 0 | Q9: =IF(AND(ISNUMBER(B9),L9="标准件"),_xlfn.XLOOKUP(B9,[1]编码对照表!$A:$A,[1]编码对照表!$E:$E),"-") -> - | R9: =IF(AND(ISNUMBER(B9),L9="标准件"),_xlfn.XLOOKUP(B9,[1]编码对照表!$A:$A,[1]编码对照表!$F:$F),"-") -> -
K10: =G10*J10 -> 0 | Q10: =IF(AND(ISNUMBER(B10),L10="标准件"),_xlfn.XLOOKUP(B10,[1]编码对照表!$A:$A,[1]编码对照表!$E:$E),"-") -> - | R10: =IF(AND(ISNUMBER(B10),L10="标准件"),_xlfn.XLOOKUP(B10,[1]编码对照表!$A:$A,[1]编码对照表!$F:$F),"-") -> -
K11: =G11*J11 -> 0 | Q11: =IF(AND(ISNUMBER(B11),L11="标准件"),_xlfn.XLOOKUP(B11,[1]编码对照表!$A:$A,[1]编码对照表!$E:$E),"-") -> - | R11: =IF(AND(ISNUMBER(B11),L11="标准件"),_xlfn.XLOOKUP(B11,[1]编码对照表!$A:$A,[1]编码对照表!$F:$F),"-") -> -
K12: =G12*J12 -> 0 | Q12: =IF(AND(ISNUMBER(B12),L12="标准件"),_xlfn.XLOOKUP(B12,[1]编码对照表!$A:$A,[1]编码对照表!$E:$E),"-") -> - | R12: =IF(AND(ISNUMBER(B12),L12="标准件"),_xlfn.XLOOKUP(B12,[1]编码对照表!$A:$A,[1]编码对照表!$F:$F),"-") -> -
K13: =G13*J13 -> 0 | Q13: =IF(AND(ISNUMBER(B13),L13="标准件"),_xlfn.XLOOKUP(B13,[1]编码对照表!$A:$A,[1]编码对照表!$E:$E),"-") -> - | R13: =IF(AND(ISNUMBER(B13),L13="标准件"),_xlfn.XLOOKUP(B13,[1]编码对照表!$A:$A,[1]编码对照表!$F:$F),"-") -> -
K14: =G14*J14 -> 0 | Q14: =IF(AND(ISNUMBER(B14),L14="标准件"),_xlfn.XLOOKUP(B14,[1]编码对照表!$A:$A,[1]编码对照表!$E:$E),"-") -> - | R14: =IF(AND(ISNUMBER(B14),L14="标准件"),_xlfn.XLOOKUP(B14,[1]编码对照表!$A:$A,[1]编码对照表!$F:$F),"-") -> -
... K139: =G139*J139 -> 0 | Q139: =IF(AND(ISNUMBER(B139),L139="标准件"),_xlfn.XLOOKUP(B139,[1]编码对照表!$A:$A,[1]编码对照表!$E:$E),"-") -> - | R139: =IF(AND(ISNUMBER(B139),L139="标准件"),_xlfn.XLOOKUP(B139,[1]编码对照表!$A:$A,[1]编码对照表!$F:$F),"-") -> -
K140: =G140*J139 -> 0 | Q140: =IF(AND(ISNUMBER(B140),L140="标准件"),_xlfn.XLOOKUP(B140,[1]编码对照表!$A:$A,[1]编码对照表!$E:$E),"-") -> - | R140: =IF(AND(ISNUMBER(B140),L140="标准件"),_xlfn.XLOOKUP(B140,[1]编码对照表!$A:$A,[1]编码对照表!$F:$F),"-") -> -
K141: =G141*J140 -> 0 | Q141: =IF(AND(ISNUMBER(B141),L141="标准件"),_xlfn.XLOOKUP(B141,[1]编码对照表!$A:$A,[1]编码对照表!$E:$E),"-") -> - | R141: =IF(AND(ISNUMBER(B141),L141="标准件"),_xlfn.XLOOKUP(B141,[1]编码对照表!$A:$A,[1]编码对照表!$F:$F),"-") -> -
K142: =G142*J141 -> 0 | Q142: =IF(AND(ISNUMBER(B142),L142="标准件"),_xlfn.XLOOKUP(B142,[1]编码对照表!$A:$A,[1]编码对照表!$E:$E),"-") -> - | R142: =IF(AND(ISNUMBER(B142),L142="标准件"),_xlfn.XLOOKUP(B142,[1]编码对照表!$A:$A,[1]编码对照表!$F:$F),"-") -> -
K143: =G143*J142 -> 0 | Q143: =IF(AND(ISNUMBER(B143),L143="标准件"),_xlfn.XLOOKUP(B143,[1]编码对照表!$A:$A,[1]编码对照表!$E:$E),"-") -> - | R143: =IF(AND(ISNUMBER(B143),L143="标准件"),_xlfn.XLOOKUP(B143,[1]编码对照表!$A:$A,[1]编码对照表!$F:$F),"-") -> -
K144: =G144*J143 -> 0 | Q144: =IF(AND(ISNUMBER(B144),L144="标准件"),_xlfn.XLOOKUP(B144,[1]编码对照表!$A:$A,[1]编码对照表!$E:$E),"-") -> - | R144: =IF(AND(ISNUMBER(B144),L144="标准件"),_xlfn.XLOOKUP(B144,[1]编码对照表!$A:$A,[1]编码对照表!$F:$F),"-") -> -
K145: =G145*J144 -> 0 | Q145: =IF(AND(ISNUMBER(B145),L145="标准件"),_xlfn.XLOOKUP(B145,[1]编码对照表!$A:$A,[1]编码对照表!$E:$E),"-") -> - | R145: =IF(AND(ISNUMBER(B145),L145="标准件"),_xlfn.XLOOKUP(B145,[1]编码对照表!$A:$A,[1]编码对照表!$F:$F),"-") -> -
K146: =G146*J145 -> 0 | Q146: =IF(AND(ISNUMBER(B146),L146="标准件"),_xlfn.XLOOKUP(B146,[1]编码对照表!$A:$A,[1]编码对照表!$E:$E),"-") -> - | R146: =IF(AND(ISNUMBER(B146),L146="标准件"),_xlfn.XLOOKUP(B146,[1]编码对照表!$A:$A,[1]编码对照表!$F:$F),"-") -> -
K147: =G147*J146 -> 0 | Q147: =IF(AND(ISNUMBER(B147),L147="标准件"),_xlfn.XLOOKUP(B147,[1]编码对照表!$A:$A,[1]编码对照表!$E:$E),"-") -> - | R147: =IF(AND(ISNUMBER(B147),L147="标准件"),_xlfn.XLOOKUP(B147,[1]编码对照表!$A:$A,[1]编码对照表!$F:$F),"-") -> -
K148: =G148*J147 -> 0 | Q148: =IF(AND(ISNUMBER(B148),L148="标准件"),_xlfn.XLOOKUP(B148,[1]编码对照表!$A:$A,[1]编码对照表!$E:$E),"-") -> - | R148: =IF(AND(ISNUMBER(B148),L148="标准件"),_xlfn.XLOOKUP(B148,[1]编码对照表!$A:$A,[1]编码对照表!$F:$F),"-") -> -
K149: =G149*J148 -> 0 | Q149: =IF(AND(ISNUMBER(B149),L149="标准件"),_xlfn.XLOOKUP(B149,[1]编码对照表!$A:$A,[1]编码对照表!$E:$E),"-") -> - | R149: =IF(AND(ISNUMBER(B149),L149="标准件"),_xlfn.XLOOKUP(B149,[1]编码对照表!$A:$A,[1]编码对照表!$F:$F),"-") -> -
K150: =G150*J149 -> 0 | Q150: =IF(AND(ISNUMBER(B150),L150="标准件"),_xlfn.XLOOKUP(B150,[1]编码对照表!$A:$A,[1]编码对照表!$E:$E),"-") -> - | R150: =IF(AND(ISNUMBER(B150),L150="标准件"),_xlfn.XLOOKUP(B150,[1]编码对照表!$A:$A,[1]编码对照表!$F:$F),"-") -> -
K151: =G151*J150 -> 0 | Q151: =IF(AND(ISNUMBER(B151),L151="标准件"),_xlfn.XLOOKUP(B151,[1]编码对照表!$A:$A,[1]编码对照表!$E:$E),"-") -> - | R151: =IF(AND(ISNUMBER(B151),L151="标准件"),_xlfn.XLOOKUP(B151,[1]编码对照表!$A:$A,[1]编码对照表!$F:$F),"-") -> -
... K156: =G156*J155 -> 0 | Q156: =IF(AND(ISNUMBER(B156),L156="标准件"),_xlfn.XLOOKUP(B156,[1]编码对照表!$A:$A,[1]编码对照表!$E:$E),"-") -> - | R156: =IF(AND(ISNUMBER(B156),L156="标准件"),_xlfn.XLOOKUP(B156,[1]编码对照表!$A:$A,[1]编码对照表!$F:$F),"-") -> -
K157: =G157*J157 -> 0 | Q157: =IF(AND(ISNUMBER(B157),L157="标准件"),_xlfn.XLOOKUP(B157,[1]编码对照表!$A:$A,[1]编码对照表!$E:$E),"-") -> - | R157: =IF(AND(ISNUMBER(B157),L157="标准件"),_xlfn.XLOOKUP(B157,[1]编码对照表!$A:$A,[1]编码对照表!$F:$F),"-") -> -
K158: =G158*J158 -> 0 | Q158: =IF(AND(ISNUMBER(B158),L158="标准件"),_xlfn.XLOOKUP(B158,[1]编码对照表!$A:$A,[1]编码对照表!$E:$E),"-") -> - | R158: =IF(AND(ISNUMBER(B158),L158="标准件"),_xlfn.XLOOKUP(B158,[1]编码对照表!$A:$A,[1]编码对照表!$F:$F),"-") -> -
K159: =G159*J159 -> 0 | Q159: =IF(AND(ISNUMBER(B159),L159="标准件"),_xlfn.XLOOKUP(B159,[1]编码对照表!$A:$A,[1]编码对照表!$E:$E),"-") -> - | R159: =IF(AND(ISNUMBER(B159),L159="标准件"),_xlfn.XLOOKUP(B159,[1]编码对照表!$A:$A,[1]编码对照表!$F:$F),"-") -> -
K160: =G160*J160 -> 0 | Q160: =IF(AND(ISNUMBER(B160),L160="标准件"),_xlfn.XLOOKUP(B160,[1]编码对照表!$A:$A,[1]编码对照表!$E:$E),"-") -> - | R160: =IF(AND(ISNUMBER(B160),L160="标准件"),_xlfn.XLOOKUP(B160,[1]编码对照表!$A:$A,[1]编码对照表!$F:$F),"-") -> -
K161: =G161*J161 -> 0 | Q161: =IF(AND(ISNUMBER(B161),L161="标准件"),_xlfn.XLOOKUP(B161,[1]编码对照表!$A:$A,[1]编码对照表!$E:$E),"-") -> - | R161: =IF(AND(ISNUMBER(B161),L161="标准件"),_xlfn.XLOOKUP(B161,[1]编码对照表!$A:$A,[1]编码对照表!$F:$F),"-") -> -
K162: =G162*J162 -> 0 | Q162: =IF(AND(ISNUMBER(B162),L162="标准件"),_xlfn.XLOOKUP(B162,[1]编码对照表!$A:$A,[1]编码对照表!$E:$E),"-") -> - | R162: =IF(AND(ISNUMBER(B162),L162="标准件"),_xlfn.XLOOKUP(B162,[1]编码对照表!$A:$A,[1]编码对照表!$F:$F),"-") -> -
K163: =G163*J163 -> 0 | Q163: =IF(AND(ISNUMBER(B163),L163="标准件"),_xlfn.XLOOKUP(B163,[1]编码对照表!$A:$A,[1]编码对照表!$E:$E),"-") -> - | R163: =IF(AND(ISNUMBER(B163),L163="标准件"),_xlfn.XLOOKUP(B163,[1]编码对照表!$A:$A,[1]编码对照表!$F:$F),"-") -> -
K164: =G164*J164 -> 0 | Q164: =IF(AND(ISNUMBER(B164),L164="标准件"),_xlfn.XLOOKUP(B164,[1]编码对照表!$A:$A,[1]编码对照表!$E:$E),"-") -> - | R164: =IF(AND(ISNUMBER(B164),L164="标准件"),_xlfn.XLOOKUP(B164,[1]编码对照表!$A:$A,[1]编码对照表!$F:$F),"-") -> -
K165: =G165*J165 -> 0 | Q165: =IF(AND(ISNUMBER(B165),L165="标准件"),_xlfn.XLOOKUP(B165,[1]编码对照表!$A:$A,[1]编码对照表!$E:$E),"-") -> - | R165: =IF(AND(ISNUMBER(B165),L165="标准件"),_xlfn.XLOOKUP(B165,[1]编码对照表!$A:$A,[1]编码对照表!$F:$F),"-") -> -
K166: =G166*J166 -> 0 | Q166: =IF(AND(ISNUMBER(B166),L166="标准件"),_xlfn.XLOOKUP(B166,[1]编码对照表!$A:$A,[1]编码对照表!$E:$E),"-") -> - | R166: =IF(AND(ISNUMBER(B166),L166="标准件"),_xlfn.XLOOKUP(B166,[1]编码对照表!$A:$A,[1]编码对照表!$F:$F),"-") -> -
K167: =G167*J167 -> 0 | Q167: =IF(AND(ISNUMBER(B167),L167="标准件"),_xlfn.XLOOKUP(B167,[1]编码对照表!$A:$A,[1]编码对照表!$E:$E),"-") -> - | R167: =IF(AND(ISNUMBER(B167),L167="标准件"),_xlfn.XLOOKUP(B167,[1]编码对照表!$A:$A,[1]编码对照表!$F:$F),"-") -> -
K168: =G168*J168 -> 0 | Q168: =IF(AND(ISNUMBER(B168),L168="标准件"),_xlfn.XLOOKUP(B168,[1]编码对照表!$A:$A,[1]编码对照表!$E:$E),"-") -> - | R168: =IF(AND(ISNUMBER(B168),L168="标准件"),_xlfn.XLOOKUP(B168,[1]编码对照表!$A:$A,[1]编码对照表!$F:$F),"-") -> -
...

Sheet 模板
A1: 项目名称 | C1: XX项目/XX项目补料计划/XX项目第XX批次 （如DZ1296项目电气预焊件、DZ1296框架补料计划、DZ1296框架第一批次） | I1: 编制 | J1: XXX （填写项目负责人） | L1: 下发时间 | M1: XXX （填写当天下发的时间，如2023.11.13） | N1: 版本号（V0/V1/V2） | O1: V0 （说明：版本变更按V0、V1依次升序） | Q1: 油漆零部件重量（吨） | R1: 该份清单需要油漆的总重量 | T1: 工序类别 | U1: 制作工位 | V1: 制作小组 | W1: 开工日期 | X1: 完工日期
A2: 序号 | B2: 代号 | C2: 名称 | D2: 所属代号 | E2: 所属部件 | F2: 所属数量 | G2: 单台数量 | H2: 计划数量 | I2: 材质 | J2: 单件重量 | K2: 单台总重 | L2: 属性 | M2: 总工艺路线（杜总新增） （此列为后续F-MOM提取数据，用于工单自动生成） | N2: 工艺内容（用于员工报工） | O2: 备注 | P2: 是否发货件 | Q2: 面漆颜色 | R2: 标准编码 | S2: 标准品名
A3: 发货件序号/焊接件序号（子件不备注序号） | B3: 子项编码 | C3: 子项名称 | D3: 父项编码 | E3: 父项名称 | F3: 单个部件所对应的子件数量 | G3: 单台部件数量 | I3: ①材料材质 ②焊接件防止漏展开导致计划物料少下，给单元格进行整行颜色标记标记规则如下 零级部件：灰色(特殊订单的使用，例如铁建罐体) 一级部件：标准色-绿色 二级部件：标准色-浅蓝 三级部件：标准色-橙色 四级部件：标准色-紫色 | K3: 单台总重=单台数量*单件重量 | L3: 属性只有：自制、外协、外购、标准件、消耗库存、客户提供 ①自制（含工序外协）：厂内买材料厂内加工/厂内买材料外协厂加工 ②外协：提供图纸，整体外包 ③外购：国家标准如GB系列、市面上常有的成品. ④消耗库存：消耗厂内呆滞物料/改制厂内物料 ⑤客户提供：客供件 备注：特殊物料/单独类型物料的外购外协属性有差异，与计划、采购沟通保持一致 | M3: 1.预处理：抛丸、底漆 2、激光、等割、剪 3.锯、锯-割（包含氧割、气割，型材切割机的割舌、割边、编程机器下料） 4.折弯、卷（卷圆、卷锥）、弯、校平 5.钻（含冲孔：角钢冲孔机，相贯线）、铣坡口 6.铆焊（含改制：利用消耗呆滞物料、返修） 7.涂装（喷砂、打胶、喷漆、喷粉） 8.装配（部装、二次装配统称为装配） 9.发运 10.工序外协 11.外购：因属性是外购，故工艺路线分为外购件 12.外协：外协分为整体外协（一般指焊接件）和外协件（单个零件/机加零件） | N3: 1.板材下料：激光、等割、剪 2.型材下料：锯-手割（氧割、气割统一称为手割，可直接锯床下料的写锯）、型材切割机（割舌、割边、编程机器下料）、冲孔（角钢冲孔机） 3.成型：折弯、卷（卷圆、卷锥）、热弯（人工火焰烧红弯）、弯管（弯管机）、校平（指机器校平）、校火（人工火焰校直或者校平）、 4.机加：相贯线（摩泰）、钻孔改为钻，攻丝分为两种：（钻-攻丝，激光-攻丝），筛选清单需同步筛选钻及攻丝、手割坡口（人工开）、机械坡口（铣边机开） 5.铆焊：组焊-打磨工序统一为组焊/组焊（机器人）、含改制 6.喷漆/喷粉（喷漆默认喷底漆、面漆都做，单独做底漆，需单独备注） 7.装配（部装、二次装配统称为装配） 8.发货（分为发货和散件发货，散件发货一般指焊接件底下有子件部件需要单独发货） 9.工序外协（车、铣、刨、磨、镗孔、插、相贯线、线切割、冲压，表面处理：镀锌、发蓝、发黑、镀铬、酸洗磷化等，热处理：正火、退火、淬火、回火、调质） 10.外购：因属性是外购，故工艺路线分为外购件 11.外协：外协分为整体外协（一般指焊接件）和外协件（单个零件/机加零件） 12.预处理：抛丸、喷砂（①一般喷粉/喷塑抛丸后是不做预处理底漆，②整体喷砂产品是不需要做预处理底漆，③产品未备注不做预处理底漆一般默认抛丸后做预处理底漆） 13.改制利用（消耗呆滞物料、返修) 备注：单独的发货件/装配件及喷漆工序在清单注明 | O3: 选填项 （如：可以填写清单改动内容/提示或者其他要求、） 1.补料原因备注在备注里 2.技改物料备注技改单号（客户提供了技改单号，若无则说明原因） 3.爱达提供 | P3: 选填项： 1、发货清单能体现在工艺清单的请勾选发货件，节约时间成本 2、标准件标注说明： a、工序为配焊为铆焊班组领用； b、备注为装配，表示有发运或装配领用进行总体装配用； c、备注为发货件，表示由发运领用，直接打包发货。 | Q3: 面漆颜色或色号 （举例：如深灰色RAL7046、蓝色RAL5012） | T3: 以 5 号车（“5” 标识）框架（“K” 标识）为核心，后续将按立柱、箱体、框架、框架附属件四大类工序对 K5 系列部件进行拆分，各工序对应部件如下： 1.立柱工序：对应部件为K5 立柱。 2.箱体工序：对应部件为K5 右上箱体、K5 左下箱体、K5 中箱体。 3.框架工序：对应部件为K5 上框架、K5 下框架、K5 中间框架。 4.框架附属件工序：对应部件为K5 框架附属件。

Sheet 工艺路线
A1: 工艺路线规范（以下工艺针对现有厂内加工能力制定）
A2: 序号 | B2: 部门 | C2: 小组 | D2: 总工艺路线 | E2: 工艺内容 | F2: 备注
A3: 1 | B3: 下料车间 | C3: 成型组、型材组 | D3: 预处理 | E3: 抛丸 | F3: ①一般喷粉抛丸后是不做预处理底漆， ②产品未备注不做预处理底漆一般默认抛丸后做预处理底漆
E4: 预处理底漆
A5: 2 | B5: 下料车间 | C5: 外包板材下料组 | D5: 激光 | E5: 激光 | F5: 板材激光切割机下料，适用于孔多，加工要求严产品
D6: 等割 | E6: 等割 | F6: 板材精细等离子下料 | H6: 激光 等割 剪 折弯 卷 弯 锯 钻 冲 攻 手割 配焊 拼焊 组焊 配装 倒圆角 校 试压 装配 发货 散件发货 工序外协
C7: 成型组 | D7: 剪 | E7: 剪 | F7: 剪板机下料，剪板下料范围8mm以下
A8: 3 | B8: 下料车间 | C8: 成型组 | D8: 折 | E8: 折弯 | F8: 折弯机折弯板材或者棒材
D9: 卷 | E9: 卷圆、卷锥 | F9: 适用于板材卷圆、槽钢、角钢、H型钢卷圆、薄板卷锥，如t2/Q235B板卷锥
D10: 弯 | E10: 弯管 | F10: 机器弯管、棒材人工手弯
D11: 校平 | E11: 机器校平 | F11: 机器校平
A12: 4 | B12: 下料车间 | C12: 型材组 | D12: 锯 | E12: 锯 | F12: 锯床下料
D13: 锯割 | E13: 锯手割 | F13: 氧割、气割统一称为手割，因此计划需给型材下料班，故加一个“锯”字
E14: 锯机割 | F14: 型材切割机下料（割舌、割边）、指摩泰等离子设备下料
E15: 相贯线 | F15: 管材R口下料加工
A16: 5 | B16: 下料车间 | C16: 机加组 | D16: 钻 | E16: 钻孔 | F16: 钻孔：通孔、沉头孔等；
E17: 冲孔 | F17: 冲孔：角钢冲孔机下料（下料范围40角铁-100角铁范围之间、适用于多孔角钢物料）；
E18: 攻丝 | F18: 攻丝分为两种：（钻-攻丝，激光-攻丝）
D19: 铣坡口 | E19: 机械坡口 | F19: I类焊缝，需超声波探伤的厂内，只能机加工方法，厂内可以铣边机开（零件宽度小于230mm加工不了坡口、没有夹持余量）
A20: 6 | B20: 一车间、二车间 | C20: 铆焊组 | D20: 铆焊 | E20: 手割 | F20: 人工火焰切割或者切割片切割工件、开缺口
E21: 手割坡口 | F21: 要求不高焊缝，人工气割、氧割开或者半自动切割机切割加工成I形、V形、K形坡口
E22: 热弯 | F22: 人工火焰烧红弯或者由人工冷弯（此工序由焊接班施工，故统一填写热弯工序，方便派工给焊接班）
E23: 配焊 | F23: 外购、外协回司需要焊接到产品上（如外购螺栓、百叶窗、螺纹）
E24: 拼焊 | F24: 同一零件分成几块拼焊在一起（板材、型材）
E25: 组焊 | F25: 组装焊接（如台车架立后的框架组装、机械、电气、液压流体的焊接；豪顿华产品的组装焊接、换电站的上下箱体总成焊接、辊道窑的炉体上线焊接、搅拌站的配料站总成焊接和主楼总成焊接等），以及小部件的焊接（如台车框架与箱体、拉耳的焊接）
E26: 组焊（机器人） | F26: 机器人焊接工件
E27: 倒圆角
E28: 校火 | F28: 人工火焰校直或者校平或校圆
E29: 改制 | F29: 利用（消耗呆滞物料、返修)
E30: 配装 | F30: 需要与铆焊件一起组装的标准件等
A31: 7 | B31: 一车间 | C31: 不锈钢组 | D31: 铆焊 | E31: 组焊
E32: 试压、抛光、清洗 | F32: 试压：客户要求管道试压、捡漏或者我们在进行压力容器制作时，需填写试压工序；清洗：指厂内机械抛光，多用于不锈钢表面抛光，一般使用羊毛轮、砂纸等或者拉丝机，以手工操作为主.
A33: 8 | B33: 三车间 | C33: 油漆班 | D33: 涂装 | E33: 喷砂 | F33: 整体喷砂产品是不需要做预处理底漆
E34: 打胶 | F34: 打胶：产品有密封要求的，涂密封胶进行密封（图纸要求）
E35: 喷漆 | F35: 每个产品的喷漆要求按技术标准执行（如只单独喷底漆、单独喷面漆、喷底漆+中途+面漆）等，此技术文件每批次单独下发工艺标准文件，不在清单中描述。
E36: 喷粉
A37: 9 | B37: 三车间 | C37: 装配组 | D37: 装配 | E37: 套丝 | F37: 管材上套丝，如套R1锥螺纹、G1管螺纹
E38: 装配
A39: 10 | B39: 三车间 | C39: 发货组 | D39: 发运 | E39: 涂油 | F39: 单独的发货机加件：客户有涂油防锈保护要求的把涂油工序加上
E40: 发货 | F40: 指本部件/本零件单独发货
...

Sheet 工艺路线辅助表
A1: 工艺路线
A2: 激光
A3: 等割
A4: 剪
A5: 锯
A6: 组焊
A7: 配装
A8: 装配
A9: 发货
A10: 外协相贯线
A11: 散件发货
A12: 工序外协
... A159: 等割-机械坡口-钻孔
